Workbook

Sheet Summary
A1: Guardian deployment test: Cortex platform tenant
A3: Tenant
A4: Tenant type (for example Cortex Cloud)
A5: Guardian content version
A6: Model provider and deployment
A7: Tester(s)
A8: Started
A9: Finished
A11: How to use this file
A12: 1. Make a copy of this file for each tenant.
A13: 2. Work through the Tests tab top to bottom.
A14: 3. Set each test's Status (it starts as "Not run").
... A19: Progress
A20: Part | B20: Tests | C20: Not run | D20: Pass | E20: Fail | F20: Blocked | G20: Skipped | H20: N/A | I20: Done | J20: % done
A21: 0 Before the session | B21: =COUNTIF(Tests!$B$2:$B$200,"0 Before") | C21: =COUNTIFS(Tests!$B$2:$B$200,"0 Before",Tests!$I$2:$I$200,"Not run") | D21: =COUNTIFS(Tests!$B$2:$B$200,"0 Before",Tests!$I$2:$I$200,"Pass") | E21: =COUNTIFS(Tests!$B$2:$B$200,"0 Before",Tests!$I$2:$I$200,"Fail") | F21: =COUNTIFS(Tests!$B$2:$B$200,"0 Before",Tests!$I$2:$I$200,"Blocked") | G21: =COUNTIFS(Tests!$B$2:$B$200,"0 Before",Tests!$I$2:$I$200,"Skipped") | H21: =COUNTIFS(Tests!$B$2:$B$200,"0 Before",Tests!$I$2:$I$200,"N/A") | I21: =B21-C21 | J21: =IF(B21=0,0,I21/B21)
A22: Part 1: without a model | B22: =COUNTIF(Tests!$B$2:$B$200,"1 No model") | C22: =COUNTIFS(Tests!$B$2:$B$200,"1 No model",Tests!$I$2:$I$200,"Not run") | D22: =COUNTIFS(Tests!$B$2:$B$200,"1 No model",Tests!$I$2:$I$200,"Pass") | E22: =COUNTIFS(Tests!$B$2:$B$200,"1 No model",Tests!$I$2:$I$200,"Fail") | F22: =COUNTIFS(Tests!$B$2:$B$200,"1 No model",Tests!$I$2:$I$200,"Blocked") | G22: =COUNTIFS(Tests!$B$2:$B$200,"1 No model",Tests!$I$2:$I$200,"Skipped") | H22: =COUNTIFS(Tests!$B$2:$B$200,"1 No model",Tests!$I$2:$I$200,"N/A") | I22: =B22-C22 | J22: =IF(B22=0,0,I22/B22)
A23: Part 2: connect the model | B23: =COUNTIF(Tests!$B$2:$B$200,"2 Model") | C23: =COUNTIFS(Tests!$B$2:$B$200,"2 Model",Tests!$I$2:$I$200,"Not run") | D23: =COUNTIFS(Tests!$B$2:$B$200,"2 Model",Tests!$I$2:$I$200,"Pass") | E23: =COUNTIFS(Tests!$B$2:$B$200,"2 Model",Tests!$I$2:$I$200,"Fail") | F23: =COUNTIFS(Tests!$B$2:$B$200,"2 Model",Tests!$I$2:$I$200,"Blocked") | G23: =COUNTIFS(Tests!$B$2:$B$200,"2 Model",Tests!$I$2:$I$200,"Skipped") | H23: =COUNTIFS(Tests!$B$2:$B$200,"2 Model",Tests!$I$2:$I$200,"N/A") | I23: =B23-C23 | J23: =IF(B23=0,0,I23/B23)
A24: Part 3: with the model | B24: =COUNTIF(Tests!$B$2:$B$200,"3 With model") | C24: =COUNTIFS(Tests!$B$2:$B$200,"3 With model",Tests!$I$2:$I$200,"Not run") | D24: =COUNTIFS(Tests!$B$2:$B$200,"3 With model",Tests!$I$2:$I$200,"Pass") | E24: =COUNTIFS(Tests!$B$2:$B$200,"3 With model",Tests!$I$2:$I$200,"Fail") | F24: =COUNTIFS(Tests!$B$2:$B$200,"3 With model",Tests!$I$2:$I$200,"Blocked") | G24: =COUNTIFS(Tests!$B$2:$B$200,"3 With model",Tests!$I$2:$I$200,"Skipped") | H24: =COUNTIFS(Tests!$B$2:$B$200,"3 With model",Tests!$I$2:$I$200,"N/A") | I24: =B24-C24 | J24: =IF(B24=0,0,I24/B24)
A25: Total | B25: =COUNTA(Tests!$B$2:$B$200) | C25: =COUNTIF(Tests!$I$2:$I$200,"Not run") | D25: =COUNTIF(Tests!$I$2:$I$200,"Pass") | E25: =COUNTIF(Tests!$I$2:$I$200,"Fail") | F25: =COUNTIF(Tests!$I$2:$I$200,"Blocked") | G25: =COUNTIF(Tests!$I$2:$I$200,"Skipped") | H25: =COUNTIF(Tests!$I$2:$I$200,"N/A") | I25: =B25-C25 | J25: =IF(B25=0,0,I25/B25)

Sheet Tests
A1: ID | B1: Part | C1: Section | D1: Test | E1: Steps | F1: Expected | G1: Billed | H1: Optional | I1: Status | J1: Evidence | K1: Notes | L1: Date | M1: By
A2: B1 | B2: 0 Before | C2: 0 Before the session | D2: Part 1: content installed | E2: The Guardian content is installed. On a tenant without layouts, some layouts, issue types or dashboards may not have installed: test P1 records what is there. | F2: Ready | I2: Not run
A3: B2 | B3: 0 Before | C3: 0 Before the session | D3: Part 1: account permissions | E3: You have an account that can create integration instances, run commands in a War Room, read Lists and set an issue's playbook. | F3: Ready | I3: Not run
A4: B3 | B4: 0 Before | C4: 0 Before the session | D4: Part 1: Core REST API key | E4: A Standard-level API key and its key ID, for the Core REST API instance (P4). docs/cortex-platform/README.md, "Prerequisites", says how to create one. | F4: Ready | I4: Not run
A5: B4 | B5: 0 Before | C5: 0 Before the session | D5: Part 1: test issues chosen | E5: Test issues chosen: one workbench issue; two or three investigation issues of different kinds (one you believe is a false positive, one real finding, one with entities such as an IP address, host, user or hash); and one spare issue that may be closed: a test issue, not a real alert (S3 targets it and O2 closes it). Guardian adds notes and fields to these issues. It cannot close them or change anything else without an approval. | F5: Ready | I5: Not run
A6: B5 | B6: 0 Before | C6: 0 Before the session | D6: Part 2: model account ready | E6: The model provider account is ready, following docs/MODEL_SETUP.md. For Microsoft Foundry: an app registration (it appears under Enterprise applications) with either a client secret or the public certificate uploaded (then the combined PEM file, private key and certificate, at hand), a role on the Foundry resource, and a custom subdomain on the resource. | F6: Ready | I6: Not run
A7: B6 | B7: 0 Before | C7: 0 Before the session | D7: Part 2: network access | E7: The tenant can reach the model over HTTPS (443): the Foundry resource endpoint and, for Entra ID, login.microsoftonline.com. If the Foundry resource limits networks (Selected networks), the tenant's outbound IP addresses are allowed. | F7: Ready | I7: Not run
A8: B7 | B8: 0 Before | C8: 0 Before the session | D8: Part 2: token quota | E8: The deployment has enough tokens-per-minute quota. A Guardian turn is tens of thousands of tokens, and a small quota answers HTTP 429. | F8: Ready | I8: Not run
A9: P1 | B9: 1 No model | C9: 1 Preflight | D9: Content present | E9: In the scripts, playbooks, lists and integrations pages, search for Guardian. Count what is installed. | F9: 3 integrations (Guardian Foundry, Guardian Vertex, Guardian Cohere), 77 automations, 21 playbooks, 25 lists, 15 issue fields, 10 indicator fields, 2 issue types, 1 indicator type. On this profile, record any layouts, issue types or dashboards that are missing. | I9: Not run
A10: P2 | B10: 1 No model | C10: 1 Preflight | D10: Content editable | E10: Open one Guardian automation and one Guardian list. | F10: If the content was installed item by item (not as a pack), both can be edited. A pack install makes them read-only. Record which you have. | I10: Not run
A11: P3 | B11: 1 No model | C11: 1 Preflight | D11: Playbooks adopted | E11: Open the playbooks GuardianInvestigateIssue and GuardianHousekeeping. | F11: No "playbook is not adopted" message. If there is one, adopt the playbooks (docs/cortex-platform/README.md, "Adopt the playbooks"). | I11: Not run
A12: P4 | B12: 1 No model | C12: 1 Preflight | D12: Core REST API instance | E12: Create a Core REST API instance (docs/cortex-platform/README.md, "Prerequisites"): the Core Server URL from Copy API URL, the Standard key ID and key. Press Test, then run !core-api-post uri=/settings/integration/search body={"size":1} | F12: Success, then a JSON result with no error. This is not a model. Guardian uses it to write results onto the issue, to read the provider instances (!guardian-model, the model probe), and for housekeeping, case capture and simulated issues. Without it, those fail and the run summary on the issue stays empty. | I12: Not run
A13: P5 | B13: 1 No model | C13: 1 Preflight | D13: Bootstrap | E13: !GuardianBootstrap | F13: It creates the runtime lists: guardian_kill_switch, guardian_audit, guardian_cost_ledger, guardian_memory, guardian_approvals_ledger, guardian_jobs_registry, guardian_seed_version, guardian_skills_crud_index, guardian_model_calibration, guardian_model_profile. Run it before every other test: nothing else creates these lists. Running it again is safe. | I13: Not run
... A26: L8 | B26: 1 No model | C26: 2 Control lists | D26: Skills and knowledge base | E26: !getList listName=guardian_skills_index, then !getList listName=guardian_kb_soc_investigation | F26: Ten skills: cortex_issue_reference, cortex_xql, cortex_detection_investigation, cortex_posture_misconfiguration, cortex_identity_risk, cortex_vulnerability_triage, cortex_attack_path, cortex_case_investigation, build_cortex_playbook and cortex_triage. Then 43 knowledge-base entries, each with an ATT&CK technique. | I26: Not run
A27: L9 | B27: 1 No model | C27: 2 Control lists | D27: Model catalogue | E27: !getList listName=guardian_model_catalog. The list is large (about 85 KB): check only that it opens as plain JSON, then search the War Room entry for the model you will use in Part 2 (for example gpt-5-mini). | F27: Plain JSON with "checked":"2026-10-09" and 146 models. Record whether your model is listed and its probe value: skip (a closed frontier model: its documented limits are used without a probe, M14) or confirm (an open-weight model: M7 confirms the window it is served with). A model that is not listed is sized by M7. | H27: Yes | I27: Not run
A28: H1 | B28: 1 No model | C28: 3 Tools and costs | D28: Tool catalogue | E28: !guardian-tools | F28: The tools the model will be offered: the allowlist, less the denylist, less commands this tenant does not have, trimmed to the token budget. Record which platform commands appear, and the Dropped by token budget row. This tenant may not have every module, so some of core-get-issues, core-get-cases, core-get-endpoints, core-list-risky-hosts, core-list-risky-users and xdr-xql-generic-query can be missing. A missing tool narrows what the agent can check. M8 repeats this after the model is sized. | I28: Not run
A29: H2 | B29: 1 No model | C29: 3 Tools and costs | D29: Cost report (zero) | E29: !guardian-cost | F29: "No cost has been recorded yet": no model call has been made. | I29: Not run
A30: S1 | B30: 1 No model | C30: 4 Safeguards | D30: Allowed skill read | E30: !GuardianToolBridge tool_name=GuardianSkillRead tool_args={"name":"cortex_triage"} | F30: status=ok and the skill text. An allowed read runs. | I30: Not run
A31: S2 | B31: 1 No model | C31: 4 Safeguards | D31: Allowed issue read | E31: !GuardianToolBridge tool_name=getIncidents tool_args={"id":"<workbench issue id>"} | F31: status=ok and the issue data. | I31: Not run
A32: S3 | B32: 1 No model | C32: 4 Safeguards | D32: Destructive action held | E32: !GuardianToolBridge tool_name=closeInvestigation tool_args={"id":"<spare issue id>"}, then !guardian-deny approval_id=<ID> reason="safeguard test" with the id it printed | F32: First "Action requires approval", with an approval id and risk tier destructive. Nothing is closed. Then "DENIED". A command that changes something never runs without a person. The spare issue is the target so that a mistaken approval closes nothing that matters. | I32: Not run
A33: S4 | B33: 1 No model | C33: 4 Safeguards | D33: Denylisted command denied | E33: !GuardianToolBridge tool_name=core-api-get tool_args={"uri":"/health"} | F33: status=denied (on the denylist). | I33: Not run
A34: S5 | B34: 1 No model | C34: 4 Safeguards | D34: Unknown command denied | E34: !GuardianToolBridge tool_name=NotARealCommand tool_args={} | F34: status=denied: neither allowed nor in the policy, so refused by default. | I34: Not run
A35: S6 | B35: 1 No model | C35: 4 Safeguards | D35: Tool ledger rows | E35: !GuardianLayoutToolLedger | F35: One row for each of S1 to S5, with the status each one got. | I35: Not run
A36: A1 | B36: 1 No model | C36: 5 Human approval | D36: Hold an action | E36: Hold: !GuardianToolBridge tool_name=GuardianContainmentSimulate tool_args={"endpoint_id":"lab-host-01","reason":"gate-test"} | F36: "Action requires approval", with an approval id and risk tier soft. Nothing runs. | I36: Not run
A37: A2 | B37: 1 No model | C37: 5 Human approval | D37: Pending approval listed | E37: !GuardianWidgetApprovalsQueue, then !GuardianLayoutRecommendedActions | F37: Both list the pending approval with the same id. | I37: Not run
A38: A3 | B38: 1 No model | C38: 5 Human approval | D38: Approve the action | E38: !guardian-approve approval_id=<ID> | F38: "APPROVED". | I38: Not run
A39: A4 | B39: 1 No model | C39: 5 Human approval | D39: Execute approved action | E39: Execute: the A1 command with approval_id=<ID> added at the end. | F39: status=ok. The action runs once. Do not re-run the plain A1 command: that parks a new approval. | I39: Not run
... A55: O2 | B55: 1 No model | C55: 8 Upkeep without Jobs | D55: Housekeeping playbook | E55: On the spare issue: !setPlaybook name=GuardianHousekeeping. When it finishes, run !GuardianPlaybookMonitor incident_id=<spare issue id> in the workbench issue. | F55: The playbook completes, and its last task closes the spare issue. The monitor reports the run as successful, with no failed tasks. This is how a Job would run it. | I55: Not run
A56: O3 | B56: 1 No model | C56: 8 Upkeep without Jobs | D56: Case capture | E56: Needs custom issue fields: N/A if P10 found them REJECTED or DROPPED. !GuardianCaseCapture | F56: It runs without error, and nothing is captured yet: no closed issue has a Guardian verdict. U2 repeats it after the runs. | H56: Yes | I56: Not run
A57: O4 | B57: 1 No model | C57: 8 Upkeep without Jobs | D57: Evaluation harvest | E57: Needs custom issue fields: N/A if P10 found them REJECTED or DROPPED. !GuardianEvalHarvest | F57: It runs without error, and no evaluation case is added yet. U3 repeats it. | H57: Yes | I57: Not run
A58: O5 | B58: 1 No model | C58: 8 Upkeep without Jobs | D58: Widget commands | E58: !GuardianWidgetCost, !GuardianWidgetToolLedger, !GuardianWidgetLoopHealth, !GuardianWidgetApprovalsQueue, !GuardianWidgetEventFeed | F58: Each returns a table, mostly empty for now. The approvals queue shows A9's hold. These stand in for the dashboard. | I58: Not run
A59: X1 | B59: 1 No model | C59: 9 Optional tests without a model | D59: Simulated issues | E59: Simulated issues (uses the Core REST API instance from P4): !GuardianSimulateIncidents scenario=phishing count=1. Other scenarios: brute_force, malware_beacon, benign_fp, generic. | F59: A new issue tagged as simulated. Record whether the issue was created at all on this tenant. If it was, you can investigate it in Part 3 instead of a real issue. | H59: Yes | I59: Not run
A60: X2 | B60: 1 No model | C60: 9 Optional tests without a model | D60: Pre-approved bypass mode | E60: Needs custom issue fields: N/A if P10 found them REJECTED or DROPPED. Pre-approved actions: on a test issue, set the field guardianapprovalmode to bypass. Then hold as in A1 on that issue. | F60: GuardianContainmentSimulate runs without a person and is audited auto_approved=true. Destructive and credential-tier actions still wait for a person. This needs the field to be settable on that issue's type: the Guardian fields are associated only with the type Guardian Agent Run (see I3). Set it back to manual afterwards. | H60: Yes | I60: Not run
A61: X3 | B61: 1 No model | C61: 9 Optional tests without a model | D61: Dashboard import | E61: Needs custom issue fields: N/A if P10 found them REJECTED or DROPPED. Dashboard: if the tenant can import dashboards, import the Guardian Performance dashboard. An item-by-item install cannot upload it, so import it by hand from the pack's dashboard file. | F61: Record whether the import works. It fills in once Part 3 has runs, if I3 finds the fields written. | H61: Yes | I61: Not run
A62: END1 | B62: 1 No model | C62: 8 Upkeep without Jobs | D62: End of Part 1 checkpoint | E62: Check that every required test in sections 1 to 8 has passed, then run !guardian-cost. | F62: Sections 1 to 8 pass, and !guardian-cost shows no cost: nothing has called a model. Fix any failure before Part 2 (see the Troubleshooting tab). | I62: Not run
A63: M1 | B63: 2 Model | C63: 10 Model provider | D63: Foundry instance saved | E63: Create a Guardian Foundry instance with the values from docs/MODEL_SETUP.md. In Model, choose your model (for example gpt-5-mini); choose Custom (use the deployment name below) only when your deployment has another name, and then fill in Deployment name. For a certificate, set Authentication to entra-client-certificate, fill in Tenant ID and Client ID, paste the whole PEM file (private key and certificate) into Certificate and private key, PEM, leave the thumbprint empty, and fill in the passphrase only if the key is encrypted. For a client secret, set Authentication to entra-client-credentials and fill in Tenant ID, Client ID and Client secret. Save. | F63: The instance saves. Record which Authentication you used. | I63: Not run
A64: M2 | B64: 2 Model | C64: 10 Model provider | D64: PEM field kept after save | E64: Certificate only (N/A with a client secret). Close the instance and open it again. | F64: The PEM field still holds a value (shown masked). This field type has not yet been tried in a console, so record the result. If the value is lost on save, switch to entra-client-credentials (client secret) so the session can continue, and report it. | I64: Not run
A65: M3 | B65: 2 Model | C65: 10 Model provider | D65: Instance Test | E65: Press Test. | F65: Success. If the error mentions the cryptography library or the Docker image, the tenant has not pulled the demisto/crypto image this integration now runs on. | I65: Not run
A66: M4 | B66: 2 Model | C66: 10 Model provider | D66: One active provider | E66: Disable every other Guardian provider instance, then run !guardian-model. | F66: One active instance: your Foundry instance, with the model chosen in its Model dropdown (or the Deployment name when Model is Custom), and the numbers a run started now would use, each with its source. For a model in the catalogue the model size comes from the catalogue (gpt-5-mini: large), and the limits follow its input budget. Before any profile is saved, a model in the catalogue that needs no probe already shows its documented input budget, marked as saved by the run's first task (gpt-5-mini on Foundry: 173400, documented, catalogue 2026-10-09), and a line saying no profile is saved yet and that !GuardianModelProfileCheck saves it now (M14). An open-weight model in the catalogue, or a model that is not in it, shows the guardian_settings budget (28258) and says how to size it (M7). Compare with P8. | I66: Not run
A67: M14 | B67: 2 Model | C67: 10 Model provider | D67: Documented profile saved | E67: !GuardianModelProfileCheck, then !guardian-model | F67: For a model in the model catalogue that needs no probe, or that has a published cloud provider cap: the output says the model is documented, with its context window and usable input limit, and that a documented profile was written with its input budget. For gpt-5-mini on Foundry: context window 400,000, usable input limit 272,000 tokens, input budget 173,400. The list guardian_model_profile is created if it was missing. !guardian-model then shows the same input budget with the source documented and the catalogue date. Running !GuardianModelProfileCheck again keeps the same budget. An open-weight model in the catalogue: no profile is written, and the output says to confirm the served window with !guardian-probe-model (M7). A model that is not in the catalogue: no profile is written; M7 sizes it. | I67: Not run
...

Sheet Guide
A1: Overview
A2: Plan | B2: Testing a new Guardian deployment on a Cortex platform tenant
A3: What this plan is | B3: A manual test plan for the first session after Guardian content is installed on a new tenant. Everything here is done by hand in the console. No script or API calls are needed.
A4: Tenant profile | B4: This plan is written for a Cortex platform tenant where Jobs cannot be created or run and layouts cannot be customised or attached (for example, Cortex Cloud). Such a tenant has no Guardian tab, no buttons and no scheduled runs. Every one of those features has a text command that does the same work, and this plan uses those commands. A tenant that does have Jobs and layouts runs this whole plan and then the extra checks on the Jobs and layouts tab.
A5: Three parts
A6: Part | B6: What it covers | C6: Needs a model | D6: Billed
A7: 1. Without a model | B7: The installed content, the lists, the safeguards, approvals, kill switch, memory and skills, and the upkeep that Jobs run on other tenants | C7: No | D7: No
A8: 2. Connect the model | B8: The provider instance, its credential, and sizing the model | C8: Yes | D8: A few small calls
A9: 3. With the model | B9: Investigations, the conclusion gate, playbook drafting, and upkeep with real run data | C9: Yes | D9: Yes
A10: Where to start | B10: Part 1 can run before the model provider account exists. Finish it first: a failure in Part 1 is an install or content problem, and it is easier to find before a model is involved.
A11: Before you start | B11: Before you start, read the install guide (docs/cortex-platform/README.md); the model setup page (docs/MODEL_SETUP.md) is needed from Part 2.
A13: How to run this plan
A14: Where to type | B14: Where to type. Type commands in an issue's War Room. Pick one quiet, low-severity issue as your workbench issue for the stand-alone commands. Use separate issues for the investigations (section 11).
A15: One thing at a time | B15: One thing at a time. Run one command, wait for its result, then run the next. Never run two Guardian investigations at the same time. Do not type in an issue while its investigation is running, except to answer the agent.
A16: Billed steps | B16: Billed steps are marked (billed): they call the model and cost money. There are none in Part 1. !guardian-cost shows the running total at any time.
A17: Before every re-run | B17: Before every re-run of an investigation on the same issue, run !DeleteContext key=Guardian first.
A18: Recording | B18: Recording. Each test has an ID. Set its Status on the Tests tab (Pass, Fail, Blocked, Skipped or N/A) and put the evidence in Evidence: a screenshot name, or the War Room entry. A result that differs from the expected one is a finding: capture it anyway and write down what happened.
A19: Time | B19: Time. Part 1 takes about an hour. Parts 2 and 3 take most of half a day, mostly waiting for investigations, which take a few minutes each.
A21: What this profile can and cannot test
A22: Feature | B22: On this tenant | C22: How this plan covers it
A23: Installed content and control lists | B23: Yes | C23: Sections 1 and 2
A24: Safeguards, approvals, kill switch | B24: Yes, with commands instead of buttons | C24: Sections 4, 5, 6
A25: Memory, skills, knowledge base | B25: Yes | C25: Section 7, then section 15 with run data
A26: Upkeep that Jobs run elsewhere (housekeeping, case capture, evaluation harvest) | B26: No Jobs: run each by hand | C26: Section 8, then section 15
A27: Model provider (Foundry, Vertex, Cohere) | B27: Yes | C27: Section 10
A28: Sizing the model (the model-adaptation Job) | B28: A model in the model catalogue: its documented limits, saved by the first task of a run; no Job needed. Other models: no Job, run by hand. | C28: L9, M14, M7
A29: Investigating one issue | B29: Yes, started by hand | C29: Section 11
A30: Conclusion-quality gate | B30: Yes | C30: Section 12
A31: Playbook drafting (content engineering) | B31: Yes | C31: Section 13
A32: Scheduled queue triage (GuardianIntakeSweep Job) | B32: No Job: optional run by hand | C32: U5
A33: Guardian tab and its buttons on an issue | B33: No | C33: The !GuardianLayout* and !guardian-* commands
... A37: Guardian Performance dashboard | B37: Only if the tenant can import dashboards | C37: Optional, X3; the !GuardianWidget* commands stand in for it
A39: Section notes
A40: Section 0 Before the session | B40: For Part 1: rows B1 to B4. For Part 2 (prepare these while Part 1 runs): rows B5 to B7.
A41: Part 1: without a model | B41: Nothing in this part calls a model. Do not create the model provider instance yet: P8 checks the starting point without one.
A42: Section 2 Control lists | B42: These lists set what the agent may do. Read them and change nothing. Use !getList listName=<name> for each.
A43: Section 4 Safeguards | B43: Every action the agent takes passes through GuardianToolBridge. These tests call it by hand, in the workbench issue's War Room.
A44: Section 5 Human approval | B44: GuardianContainmentSimulate is the pack's safe stand-in for "isolate endpoint": it changes nothing and only writes a note. It passes through the same gate as real containment. Work in the workbench issue's War Room, and put the approval id that the hold step prints in place of <ID>.
A45: Section 5 Human approval (note) | B45: Credential-tier actions need confirm=CONFIRM (exact, case-sensitive) on !guardian-approve. Pending approvals expire after 60 minutes, but only when Housekeeping runs (U1).
A46: Section 6 Kill switch | B46: Change the switch only with !guardian-killswitch. Never use setList: the list is protected.
...

Sheet Jobs by hand
A1: Jobs by hand
A3: On a tenant with Jobs, six Jobs run Guardian's upkeep on a schedule.
A4: Here someone runs them by hand: at the end of each test session, and regularly once Guardian is in use.
A5: Each Job runs one playbook.
A6: The four upkeep playbooks run one script and then close the issue they run on, because a Job opens a new issue for every run.
A7: So there are two ways to run one by hand:
A8: - The script in any War Room. This is the simpler way for routine use, and nothing is closed.
A9: - The playbook on a spare issue with !setPlaybook name=<playbook>. It does exactly what a Job run does, and closes that issue at the end.
A11: Job | B11: Playbook | C11: By hand | D11: Needs a model | E11: How often
A12: GuardianHousekeeping | B12: GuardianHousekeeping | C12: !GuardianHousekeeping | D12: No | E12: Hourly on other tenants; here at least daily, and at the end of each session
A13: GuardianCaseCapture | B13: GuardianCaseCapture | C13: !GuardianCaseCapture | D13: No | E13: After closing issues that Guardian investigated (it covers the last 30 hours)
A14: GuardianEvalHarvest | B14: GuardianEvalHarvest | C14: !GuardianEvalHarvest | D14: No | E14: Daily (it covers the last 48 hours)
A15: GuardianEvalScore | B15: GuardianEvalScore | C15: !GuardianEval action=score | D15: No | E15: Only when evaluation runs exist. Evaluation runs open issues that must start a playbook by themselves, which this tenant does not do, so this Job has little to do here.
A16: GuardianModelAdaptation | B16: GuardianModelAdaptation | C16: !guardian-probe-model, then !GuardianModelProfileUpdate | D16: Yes (billed) | E16: Not needed for a model with a documented profile (M14). Otherwise after any change of model or deployment (M7).
A17: GuardianIntakeSweep | B17: GuardianAgentLoop | C17: !setPlaybook name=GuardianAgentLoop on an issue | D17: Yes (billed) | E17: Only if the customer wants queue triage (U5)
A19: Without custom issue fields | B19: GuardianCaseCapture, GuardianEvalHarvest and GuardianEvalScore find issues by the Guardian verdict field. On a tenant where P10 found custom issue fields REJECTED or DROPPED they find nothing: skip them.

Sheet Troubleshooting
A1: Symptom | B1: Likely cause
A2: !guardian-model, housekeeping or case capture fails, or the run summary stays empty | B2: No working Core REST API instance (P4)
A3: A list is missing (audit, memory, kill switch) | B3: !GuardianBootstrap was not run (P5)
A4: getList returns {"id": ..., "version": -1 ... | B4: The list was uploaded with its file wrapper; upload it again (docs/cortex-platform/MANUAL_UPLOAD.md)
A5: "playbook is not adopted" | B5: Adopt the playbooks (P3)
A6: Everything is denied | B6: The kill switch is on (!GuardianKillSwitchCheck)
A7: Test fails and mentions cryptography or the Docker image | B7: The tenant has not pulled demisto/crypto, the image Guardian Foundry runs on
A8: "Entra ID did not accept the certificate assertion" (AADSTS700027) | B8: The public certificate is not uploaded to the app registration, the thumbprint is for another certificate, or the Tenant or Client ID is wrong
A9: Entra error that the application was not found | B9: Wrong Client ID, or the app is in a different tenant from the Tenant ID
A10: HTTP 401 or 403 from Foundry | B10: No role on the resource (wait five minutes after adding one), or no custom subdomain on the resource
A11: HTTP 404 | B11: Wrong deployment name, or the project endpoint was used instead of the resource endpoint
A12: HTTP 429 | B12: The deployment's tokens-per-minute quota is too low
... A19: The probe reports a quota reached at N tokens | B19: The deployment's tokens-per-minute quota stopped the search, not its context window (B7). A closed frontier model or a model with a published cloud cap keeps its documented limit; otherwise the largest request that answered is used.

Sheet Jobs and layouts
A1: Tenant with Jobs and layouts
A3: Intro | B3: Run the whole plan, then these checks as well.
A4: Jobs | B4: Jobs: create the six Jobs (docs/cortex-platform/README.md, "Create the Jobs"). Check that GuardianHousekeeping runs hourly and that GuardianModelAdaptation writes guardian_model_profile. Enable GuardianIntakeSweep (queue triage every 6 hours) only when the customer wants scheduled triage.
A5: Issue layout | B5: Issue layout: where GuardianAgentRunLayout is attached, the Guardian tab shows the run summary, recommended actions, trace and tool ledger. Its buttons (Approve, Deny, Reply to agent, Compact transcript, Pause all runs, Resume all runs) do the same as the commands in sections 5 to 11.
A6: SOC Agent page | B6: SOC Agent page: the guardian:primary indicator page and its buttons (Refresh Tools, Agent Readiness, Validate Tools, Apply Policy, Export Config, New Investigation). Apply Policy narrows the tool allowlist; run !guardian-tools before and after it.

Sheet Changes
A1: Date | B1: ID | C1: Change | D1: In a copy made earlier
A2: 2026-10-10 | B2: L9 | C2: New: the model catalogue list | D2: Optional; run it before Part 2.
A3: 2026-10-10 | B3: L2 | C3: More to note: model_tier, max_input_tokens, incident_fields_enabled and the cap comment | D3: No re-run needed.
A4: 2026-10-10 | B4: B5 | C4: A client secret is listed next to the certificate | D4: No action.
A5: 2026-10-10 | B5: M1 | C5: Reworded: the Model dropdown, and a client secret as an alternative to the certificate | D5: No re-run needed.
A6: 2026-10-10 | B6: M2 | C6: N/A with a client secret | D6: Mark it N/A if you used a client secret.
A7: 2026-10-10 | B7: M4 | C7: Expected changed: before any profile is saved, a model in the catalogue shows its documented budget | D7: Re-run now (needs GuardianModelCommand from 2026-10-10 on the tenant).
A8: 2026-10-10 | B8: M14 | C8: New: documented profile saved | D8: Run now, after M4.
A9: 2026-10-10 | B9: M15 | C9: New: model size | D9: Run now, after M14.
A10: 2026-10-10 | B10: M7 | C10: Optional for a model with a documented profile; the budget does not change | D10: Run when you reach it.
A11: 2026-10-10 | B11: M13 | C11: Also repeats M14 and M15 | D11: No action.
A12: 2026-10-10 | B12: I1 | C12: Expected adds the Resolve model profile entry | D12: Run when you reach it.
... A28: 2026-10-13 | B28: R1, T8, U4 | C28: R1 says where the search rows are (context, not the War Room entry). T8 has now been seen on a live tenant. U4 notes that loop health shows zeros when runs happen on ordinary issues. | D28: No re-run needed.
